try{
    x = 10;
    let x = 0;

} catch (exeption) {
    throw exeption;
} finally {
    console.log("Final)
}

